Workbook

Sheet Карточка проекта
B2: Interactive Brokers Group, Inc. (NASDAQ: IBKR)
B3: Структурный разрыв доходности: почему акционер IBKR растёт быстрее, чем сама компания
B4: Период анализа: FY2024 vs FY2023 (год, завершённый 31.12.2024) · Источник: 10-K FY2024, Earnings Release 4Q2024, SEC EDGAR
B6: ЦЕЛЬ | C6: Оценить, является ли рост Interactive Brokers в 2024 году качественным (структурным, основанным на росте клиентской базы и объёмов) или конъюнктурным (зависящим от уровня процентных ставок), и проверить, насколько официальная метрика "чистая прибыль" отражает реальный результат для держателя акций IBKR — учитывая холдинговую структуру компании с неконтролирующими долями участия (NCI).
B7: ЗАДАЧИ | C7: 1) Свести P&L, баланс и операционные метрики за FY2024 и FY2023 из первичных источников (10-K, пресс-релиз о результатах). 2) Разложить рост выручки на компоненты: комиссионный доход (объём × цена) и чистый процентный доход (объём баланса × ставка). 3) Посчитать структуру владения IBG LLC (доля IBG, Inc. vs Holdings/NCI) и её влияние на показатель "Net income available for common stockholders". 4) Построить факторный разбор: на сколько изменение DARTs, комиссии за ордер и NIM объясняет изменение выручки. 5) Оценить операционный рычаг (DOL) и устойчивость pretax margin. 6) Сформулировать инвестиционный вывод и риски (чувствительность к ставке ФРС).
B8: РЕАЛИЗАЦИЯ | C8: Данные: Consolidated Statements of Income, Statements of Financial Condition, Operating Data, Net Interest Margin таблицы из официального Earnings Release 4Q2024 (interactivebrokers.com/ir) и 10-K FY2024 (SEC EDGAR, ibkr-20241231x10k.htm). Методы: горизонтальный и вертикальный анализ P&L; факторный анализ методом цепных подстановок (объём × цена/ставка) для комиссий и NII; расчёт операционного рычага (DOL = %ΔEBT / %ΔRevenue); анализ доли NCI в структуре капитала и прибыли; сценарный анализ чувствительности NII к ставке ФРС (используя раскрытую компанией чувствительность: -25 б.п. → -73 млн NII).
B9: РЕШЕНИЕ | C9: Excel-модель с 6 листами: P&L (факт + вертикальный/горизонтальный анализ), Баланс, Операционные метрики, Факторный анализ выручки, Структура NCI и EPS-разрыв, Сценарный анализ ставки. Все цифры — формулы от входных данных (лист 'Входные данные'), без хардкода в расчётных ячейках. Дополнительно: 8-слайдовая презентация и интерактивный HTML-дашборд со сценарным слайдером ставки ФРС.
B10: РЕЗУЛЬТАТЫ | C10: Net revenues +19.5% (5,185 vs 4,340 млн $), но чистая прибыль, доступная акционерам IBKR (NI available for common stockholders) выросла быстрее — на 25.8% (755 vs 600 млн $) — за счёт небольшого роста доли IBG Inc. в IBG LLC (25.4%→25.8%) и опережающего роста adjusted EPS. При этом рост объясняется на ~80% объёмом (DARTs +61%, customer accounts +30%), а не ценой/ставкой: commission per order упал на 15%, а NIM практически не изменился (2.35%→2.36%). Операционный рычаг слабый (DOL ≈ 1.05x) — non-interest expenses росли почти вровень с выручкой (+17.2% vs +19.5%), в основном из-за G&A (+48.8%). Ключевой риск: ~61% net revenue зависит от net interest income — снижение ставки ФРС на 100 б.п. сократило бы NII на ~335 млн $ (оценка компании), что эквивалентно ~6.5% от net revenues FY2024.

Sheet Входные данные
B1: ВХОДНЫЕ ДАННЫЕ — P&L (Consolidated Statements of Income), $ млн
B2: Статья | C2: FY2024 | D2: FY2023 | E2: Источник
B3: Commissions | C3: 1697 | D3: 1360 | E3: Source: IBKR Earnings Release 4Q2024, p.3, Consolidated Statements of Income, interactivebrokers.com/mkt/getFileNew.php?file=2024Q4_Earnings_Release.pdf
B4: Other fees and services | C4: 280 | D4: 197
B5: Other income (loss) | C5: 60 | D5: -11
B6: Total non-interest income | C6: 2037 | D6: 1546
B7: Interest income | C7: 7339 | D7: 6230
B8: Interest expense | C8: -4191 | D8: -3436
B9: Total net interest income | C9: 3148 | D9: 2794
B10: Total net revenues | C10: 5185 | D10: 4340
B11: Execution, clearing and distribution fees | C11: 447 | D11: 386
B12: Employee compensation and benefits | C12: 574 | D12: 527
B13: Occupancy, depreciation and amortization | C13: 101 | D13: 99
B14: Communications | C14: 39 | D14: 41
B15: General and administrative | C15: 314 | D15: 211
... B25: Weighted average diluted shares, millions | C25: 109 | D25: 105.8
B27: ВХОДНЫЕ ДАННЫЕ — Баланс (Statements of Financial Condition), $ млн
B28: Статья | C28: 31.12.2024 | D28: 31.12.2023 | E28: Источник
B29: Total assets | C29: 150518 | D29: 128423 | E29: Source: IBKR Earnings Release 4Q2024, p.5, Condensed Consolidated Statements of Financial Condition
B30: Receivables from customers, net | C30: 64432 | D30: 44472
B31: Customers payable | C31: 115343 | D31: 101012
B32: Total liabilities | C32: 133921 | D32: 114356
B33: Stockholders' equity (IBG, Inc.) | C33: 4280 | D33: 3584
B34: Noncontrolling interests | C34: 12317 | D34: 10483
B35: Total equity | C35: 16597 | D35: 14067
B37: ВХОДНЫЕ ДАННЫЕ — Структура владения IBG LLC
B38: Статья | C38: 2024 | D38: 2023 | E38: Источник
B39: Доля IBG, Inc. в IBG LLC, % | C39: 0.258 | D39: 0.254 | E39: Source: IBKR 10-K FY2024, p.3, Ownership of IBG LLC Membership Interests table
B40: Доля Holdings (NCI) в IBG LLC, % | C40: 0.742 | D40: 0.746
B42: ВХОДНЫЕ ДАННЫЕ — Операционные метрики
B43: Статья | C43: FY2024 | D43: FY2023 | E43: Источник
B44: Customer accounts, тыс. (на конец года) | C44: 3337 | D44: 2562 | E44: Source: IBKR Earnings Release 4Q2024, p.2 (Business Highlights), p.6-8 (Operating Data, Customer Statistics)
B45: Customer equity, $ млрд (на конец года) | C45: 568.2 | D45: 426
B46: Total customer DARTs, тыс. (среднее в Q4) | C46: 3118 | D46: 1934
B47: Commission per cleared order, $ (Q4) | C47: 2.72 | D47: 3.19
B48: Customer margin loans, $ млрд (на конец года) | C48: 64.2 | D48: 44.3
B49: Customer credit balances, $ млрд (на конец года) | C49: 119.7 | D49: 104
B50: Опционные контракты, млн шт. (за год) | C50: 1344.855 | D50: 1020.736
B51: Фьючерсные контракты, млн шт. (за год) | C51: 218.327 | D51: 209.034
B52: Объём акций, млн шт. (за год) | C52: 307489.71 | D52: 252742.85
...

Sheet P&L Анализ
B1: P&L: ГОРИЗОНТАЛЬНЫЙ И ВЕРТИКАЛЬНЫЙ АНАЛИЗ, $ млн
B2: Статья | C2: FY2024 | D2: FY2023 | E2: Δ, % | F2: % от revenue FY24 | G2: % от revenue FY23
B3: Commissions | C3: ='Входные данные'!C3 -> 1697 | D3: ='Входные данные'!D3 -> 1360 | E3: =IFERROR((C3-D3)/ABS(D3),"н/д") -> 0.24779412 | F3: =C3/$C$10 -> 0.32729026 | G3: =D3/$D$10 -> 0.31336406
B4: Other fees and services | C4: ='Входные данные'!C4 -> 280 | D4: ='Входные данные'!D4 -> 197 | E4: =IFERROR((C4-D4)/ABS(D4),"н/д") -> 0.4213198 | F4: =C4/$C$10 -> 0.054001929 | G4: =D4/$D$10 -> 0.045391705
B5: Other income (loss) | C5: ='Входные данные'!C5 -> 60 | D5: ='Входные данные'!D5 -> -11 | E5: =IFERROR((C5-D5)/ABS(D5),"н/д") -> 6.4545455 | F5: =C5/$C$10 -> 0.011571842 | G5: =D5/$D$10 -> -0.0025345622
B6: Total non-interest income | C6: ='Входные данные'!C6 -> 2037 | D6: ='Входные данные'!D6 -> 1546 | E6: =IFERROR((C6-D6)/ABS(D6),"н/д") -> 0.31759379 | F6: =C6/$C$10 -> 0.39286403 | G6: =D6/$D$10 -> 0.3562212
B7: Interest income | C7: ='Входные данные'!C7 -> 7339 | D7: ='Входные данные'!D7 -> 6230 | E7: =IFERROR((C7-D7)/ABS(D7),"н/д") -> 0.17800963 | F7: =C7/$C$10 -> 1.4154291 | G7: =D7/$D$10 -> 1.4354839
B8: Interest expense | C8: ='Входные данные'!C8 -> -4191 | D8: ='Входные данные'!D8 -> -3436 | E8: =IFERROR((C8-D8)/ABS(D8),"н/д") -> -0.21973225 | F8: =C8/$C$10 -> -0.80829315 | G8: =D8/$D$10 -> -0.79170507
B9: Total net interest income | C9: ='Входные данные'!C9 -> 3148 | D9: ='Входные данные'!D9 -> 2794 | E9: =IFERROR((C9-D9)/ABS(D9),"н/д") -> 0.12670007 | F9: =C9/$C$10 -> 0.60713597 | G9: =D9/$D$10 -> 0.6437788
B10: Total net revenues | C10: ='Входные данные'!C10 -> 5185 | D10: ='Входные данные'!D10 -> 4340 | E10: =IFERROR((C10-D10)/ABS(D10),"н/д") -> 0.19470046 | F10: =C10/$C$10 -> 1 | G10: =D10/$D$10 -> 1
B11: Execution, clearing and distribution fees | C11: ='Входные данные'!C11 -> 447 | D11: ='Входные данные'!D11 -> 386 | E11: =IFERROR((C11-D11)/ABS(D11),"н/д") -> 0.15803109 | F11: =C11/$C$10 -> 0.086210222 | G11: =D11/$D$10 -> 0.088940092
B12: Employee compensation and benefits | C12: ='Входные данные'!C12 -> 574 | D12: ='Входные данные'!D12 -> 527 | E12: =IFERROR((C12-D12)/ABS(D12),"н/д") -> 0.089184061 | F12: =C12/$C$10 -> 0.11070395 | G12: =D12/$D$10 -> 0.12142857
B13: Occupancy, depreciation and amortization | C13: ='Входные данные'!C13 -> 101 | D13: ='Входные данные'!D13 -> 99 | E13: =IFERROR((C13-D13)/ABS(D13),"н/д") -> 0.02020202 | F13: =C13/$C$10 -> 0.019479267 | G13: =D13/$D$10 -> 0.02281106
B14: Communications | C14: ='Входные данные'!C14 -> 39 | D14: ='Входные данные'!D14 -> 41 | E14: =IFERROR((C14-D14)/ABS(D14),"н/д") -> -0.048780488 | F14: =C14/$C$10 -> 0.0075216972 | G14: =D14/$D$10 -> 0.0094470046
... B22: Net income available for common stockholders | C22: ='Входные данные'!C22 -> 755 | D22: ='Входные данные'!D22 -> 600 | E22: =IFERROR((C22-D22)/ABS(D22),"н/д") -> 0.25833333 | F22: =C22/$C$10 -> 0.14561234 | G22: =D22/$D$10 -> 0.13824885
B24: КЛЮЧЕВЫЕ МАРЖИНАЛЬНЫЕ КОЭФФИЦИЕНТЫ
B25: Коэффициент | C25: FY2024 | D25: FY2023 | E25: Δ, п.п. | F25: Комментарий
B26: Pretax profit margin (GAAP) | C26: =C18/C10 -> 0.71263259 | D26: =D18/D10 -> 0.70714286 | E26: =(C26-D26)*100 -> 0.54897369 | F26: EBT / Net revenues — операционная эффективность с учётом ставок
B27: Net margin (доступный акционерам IBKR) | C27: =C22/C10 -> 0.14561234 | D27: =D22/D10 -> 0.13824885 | E27: =(C27-D27)*100 -> 0.73634954 | F27: Доля net revenue, реально доходящая до держателя акций IBKR
B28: Доля non-interest expenses в revenue | C28: =C17/C10 -> 0.28736741 | D28: =D17/D10 -> 0.29285714 | E28: =(C28-D28)*100 -> -0.54897369 | F28: Контроль над операционными расходами
B29: Доля NII в Total net revenues | C29: =C9/C10 -> 0.60713597 | D29: =D9/D10 -> 0.6437788 | E29: =(C29-D29)*100 -> -3.6642833 | F29: Зависимость от процентных ставок
B30: Effective tax rate | C30: =C19/C18 -> 0.077943166 | D30: =D19/D18 -> 0.083740632 | E30: =(C30-D30)*100 -> -0.57974657 | F30: Income tax / EBT
B32: ОПЕРАЦИОННЫЙ РЫЧАГ (DOL)
B33: Degree of Operating Leverage = %ΔEBT / %ΔRevenue | C33: =E18/E10 -> 1.0476361 | D33: DOL ≈ 1.0x означает, что прибыль до налога растёт практически пропорционально выручке — операционный рычаг практически не проявляется, расходы масштабируются почти 1:1 с доходом (не классический сценарий tech-платформы с падающими удельными издержками)

Sheet Баланс
B1: БАЛАНС (СОКРАЩЁННЫЙ), $ млн
B2: Статья | C2: 31.12.2024 | D2: 31.12.2023 | E2: Δ, %
B3: Total assets | C3: ='Входные данные'!C29 -> 150518 | D3: ='Входные данные'!D29 -> 128423 | E3: =(C3-D3)/D3 -> 0.17204862
B4: Receivables from customers, net | C4: ='Входные данные'!C30 -> 64432 | D4: ='Входные данные'!D30 -> 44472 | E4: =(C4-D4)/D4 -> 0.44882173
B5: Customers payable | C5: ='Входные данные'!C31 -> 115343 | D5: ='Входные данные'!D31 -> 101012 | E5: =(C5-D5)/D5 -> 0.14187423
B6: Total liabilities | C6: ='Входные данные'!C32 -> 133921 | D6: ='Входные данные'!D32 -> 114356 | E6: =(C6-D6)/D6 -> 0.17108853
B7: Stockholders' equity (IBG, Inc.) | C7: ='Входные данные'!C33 -> 4280 | D7: ='Входные данные'!D33 -> 3584 | E7: =(C7-D7)/D7 -> 0.19419643
B8: Noncontrolling interests | C8: ='Входные данные'!C34 -> 12317 | D8: ='Входные данные'!D34 -> 10483 | E8: =(C8-D8)/D8 -> 0.17494992
B9: Total equity | C9: ='Входные данные'!C35 -> 16597 | D9: ='Входные данные'!D35 -> 14067 | E9: =(C9-D9)/D9 -> 0.17985356
B11: СТРУКТУРА КАПИТАЛА И ДОЛЯ NCI
B12: Показатель | C12: 2024 | D12: 2023 | E12: Δ, п.п.
B13: Доля NCI в Total equity, % | C13: =C8/C9 -> 0.74212207 | D13: =D8/D9 -> 0.74521931 | E13: =(C13-D13)*100 -> -0.30972373
B14: ROE акционеров IBKR (NI common / Stockholders' equity), % | C14: ='P&L Анализ'!C22/C7 -> 0.17640187 | D14: ='P&L Анализ'!D22/D7 -> 0.16741071 | E14: =(C14-D14)*100 -> 0.89911549
B15: Финансовый рычаг (Total assets / Stockholders' equity), x | C15: =C3/C7 -> 35.167757 | D15: =D3/D7 -> 35.83231
B17: Примечание: баланс брокера структурно отличается от обычной компании — основная масса активов и обязательств (Receivables from customers / Customers payable) представляет собой клиентские средства, технически проходящие через баланс IBKR, а не собственный капитал компании. Поэтому традиционные коэффициенты левереджа (Assets/Equity ≈ 9x) здесь не являются индикатором риска в классическом смысле.

Sheet Факторный анализ
B2: ФАКТОРНЫЙ АНАЛИЗ: КОМИССИОННЫЙ ДОХОД (Volume × Price, метод цепных подстановок)
B3: Показатель | C3: FY2024 | D3: FY2023 | E3: Δ | F3: Источник / комментарий
B4: Total customer DARTs, тыс. (Q4, аннуализ. база) | C4: ='Входные данные'!C46 -> 3118 | D4: ='Входные данные'!D46 -> 1934 | E4: =(C4-D4)/D4 -> 0.61220269
B5: Commission per cleared order, $ (Q4) | C5: ='Входные данные'!C47 -> 2.72 | D5: ='Входные данные'!D47 -> 3.19 | E5: =(C5-D5)/D5 -> -0.14733542 | F5: Падение на ~15% — рост среднего числа мелких заявок (опционы/акции), а не повышение тарифов
B6: Commission revenue, $ млн (факт, годовой) | C6: ='Входные данные'!C3 -> 1697 | D6: ='Входные данные'!D3 -> 1360 | E6: =(C6-D6)/D6 -> 0.24779412
B8: РАЗЛОЖЕНИЕ ИЗМЕНЕНИЯ КОМИССИОННОГО ДОХОДА НА ФАКТОРЫ (упрощённая модель, прокси DARTs×price)
B9: Эффект | C9: Вклад, % от изменения комиссии | E9: Интерпретация
B10: Эффект объёма (Δ DARTs при старой цене) | C10: =(C4-D4)*D5/(D4*D5) -> 0.61220269 | E10: Положительный — рост числа сделок тянет доход вверх
B11: Эффект цены (Δ Commission/order при новом объёме) | C11: =(C5-D5)*C4/(D4*D5) -> -0.23753457 | E11: Отрицательный — падение цены за ордер тормозит рост дохода
B12: Совокупный эффект (≈ рост базы DARTs за квартал) | C12: =C10+C11 -> 0.37466812
B14: ФАКТОРНЫЙ АНАЛИЗ ЧИСТОГО ПРОЦЕНТНОГО ДОХОДА (NII): объём баланса vs ставка
B15: Показатель | C15: FY2024 | D15: FY2023 | E15: Δ | F15: Источник
B16: Customer margin loans, $ млрд (на конец года) | C16: ='Входные данные'!C48 -> 64.2 | D16: ='Входные данные'!D48 -> 44.3 | E16: =(C16-D16)/D16 -> 0.44920993
B17: Net interest margin (NIM), % годовых | C17: ='Входные данные'!C53 -> 0.0235 | D17: ='Входные данные'!D53 -> 0.0236 | E17: =(C17-D17)*100 -> -0.01 | F17: NIM почти не изменился — ставка ФРС не была драйвером роста NII
B18: Total net interest income, $ млн (факт, годовой) | C18: ='Входные данные'!C9 -> 3148 | D18: ='Входные данные'!D9 -> 2794 | E18: =(C18-D18)/D18 -> 0.12670007
B20: ВЫВОД: Рост Net revenues (+19.5%) почти полностью объясняется ростом физических объёмов — DARTs +61%, customer accounts +30%, customer margin loans +45% — при ОТРИЦАТЕЛЬНОМ ценовом эффекте (commission per order -15%) и практически неизменном NIM (2.35%→2.36%). Это означает, что результат 2024 года — это история КЛИЕНТСКОГО РОСТА, а не процентного цикла, и устойчивость прибыли в будущем зависит от способности компании удерживать клиентскую базу при возможном снижении ставок ФРС, а не от того, останутся ли ставки высокими.

Sheet NCI и EPS-разрыв
B2: СТРУКТУРНЫЙ РАЗРЫВ: КОНСОЛИДИРОВАННАЯ ПРИБЫЛЬ vs ПРИБЫЛЬ АКЦИОНЕРА IBKR
B3: Показатель | C3: FY2024 | D3: FY2023 | E3: Δ, % | F3: Комментарий
B4: Net income (вся IBG LLC, консолидированный) | C4: ='Входные данные'!C20 -> 3407 | D4: ='Входные данные'!D20 -> 2812 | E4: =(C4-D4)/D4 -> 0.21159317
B5: минус: Net income, причитающийся NCI (Holdings) | C5: ='Входные данные'!C21 -> 2652 | D5: ='Входные данные'!D21 -> 2212 | E5: =(C5-D5)/D5 -> 0.19891501
B6: Итого: Net income available for common stockholders (IBKR) | C6: =C4-C5 -> 755 | D6: =D4-D5 -> 600 | E6: =(C6-D6)/D6 -> 0.25833333
B7: Проверка (CHECK = факт из 10-K) | C7: =C6-'Входные данные'!C22 -> 0 | D7: =D6-'Входные данные'!D22 -> 0
B9: ПОЧЕМУ ФАКТИЧЕСКАЯ ДОЛЯ NCI В ПРИБЫЛИ ВЫШЕ ФОРМАЛЬНОЙ ДОЛИ ВЛАДЕНИЯ
B10: Показатель | C10: 2024 | D10: 2023 | E10: Δ, п.п.
B11: Формальная доля IBG, Inc. в IBG LLC, % | C11: ='Входные данные'!C39 -> 0.258 | D11: ='Входные данные'!D39 -> 0.254 | E11: =(C11-D11)*100 -> 0.4
B12: Фактическая доля NCI в Net income (NCI amount / Net income), % | C12: =C5/C4 -> 0.77839742 | D12: =D5/D4 -> 0.78662873 | E12: =(C12-D12)*100 -> -0.82313169
B13: Разрыв: фактическая доля NCI минус доля владения NCI, п.п. | C13: =(C12-(1-C11))*100 -> 3.6397417 | D13: =(D12-(1-D11))*100 -> 4.0628734 | E13: Точный документально подтверждённый механизм: Tax Receivable Agreement — IBG, Inc. обязана выплачивать Holdings 85% налоговой экономии от step-up в налоговой базе при выкупе долей; эти выплаты идут поверх обычного распределения прибыли (см. Note 4, 10-K FY2024)
B14: Динамика разрыва: сократился на (2024 vs 2023), п.п. | C14: =C13-D13 -> -0.42313169
B15: Справочно: средневзвешенная доля IBG, Inc. в прибыли IBG LLC за период, % | C15: 25.6% | D15: 25.0% | E15: Это другое число, чем точечная доля владения капиталом (25.8%) — техническое отличие, не отдельный структурный эффект
B17: EPS-МОСТ: РАЗЛОЖЕНИЕ РОСТА NI ДЛЯ АКЦИОНЕРОВ IBKR НА КОМПОНЕНТЫ
B18: Компонент роста NI available for common stockholders (+25.8%) | C18: Вклад, п.п. | E18: Природа фактора
B19: Рост консолидированной прибыли IBG LLC (операционный) | C19: =(C4/D4-1)*100 -> 21.159317 | E19: Объясняется ростом клиентской активности (см. лист 'Факторный анализ') — DARTs +61%, accounts +30%
B20: Остаточный эффект: рост доли владения + сокращение налогового разрыва NCI | C20: =(C6/D6-1)*100-C19 -> 4.6740161 | E20: Структурный/капитальный эффект — доля IBG Inc. в IBG LLC выросла (25.4%→25.8%) за счёт выкупа доли у Holdings, плюс сократился разрыв между долей владения и фактической налоговой долей NCI
B21: Итого рост Net income available for common stockholders | C21: =(C6/D6-1)*100 -> 25.833333

Sheet Сценарий ставки
B2: СЦЕНАРНЫЙ АНАЛИЗ: ЧУВСТВИТЕЛЬНОСТЬ К ИЗМЕНЕНИЮ СТАВКИ ФРС
B3: Базовый Net interest income FY2024, $ млн | C3: ='Входные данные'!C9 -> 3148
B4: Чувствительность NII к -100 б.п. (раскрытие компании), $ млн | C4: ='Входные данные'!C57 -> -335
B5: Базовый Net revenues FY2024, $ млн | C5: ='Входные данные'!C10 -> 5185
B6: Параметр сценария: сдвиг ставки, б.п. (введите значение) | C6: -100
B8: РЕЗУЛЬТАТ СЦЕНАРИЯ
B9: Показатель | C9: Базовый FY2024 | D9: После шока | E9: Δ | F9: Δ, %
B10: Net interest income, $ млн | C10: =C3 -> 3148 | D10: =C3+C4*(C6/-100) -> 2813 | E10: =D10-C10 -> -335 | F10: =E10/C10 -> -0.10641677
B11: Net revenues, $ млн (при неизменном комиссионном доходе) | C11: =C5 -> 5185 | D11: =C5+(D10-C10) -> 4850 | E11: =D11-C11 -> -335 | F11: =E11/C11 -> -0.06460945
B12: Income before taxes (при сохранении pretax margin FY24), $ млн | C12: =C11*'P&L Анализ'!C26 -> 3695 | D12: =D11*'P&L Анализ'!C26 -> 3456.2681 | E12: =D12-C12 -> -238.73192 | F12: =E12/C12 -> -0.06460945
B14: Модель линейна и консервативна: реальный эффект может быть смягчён ростом клиентских балансов или частично компенсирован снижением стоимости фондирования (interest expense также чувствителен к ставке). Изменяйте жёлтую ячейку 'сдвиг ставки' для проверки других сценариев (например, -200 б.п. в случае рецессии или +50 б.п. при возврате инфляции).

Sheet Cash Flow - Входные данные
B2: CONSOLIDATED STATEMENTS OF CASH FLOWS
B4: Статья ($ млн) | C4: 2024 | D4: 2023 | E4: 2022
B5: Cash flows from operating activities
B6: Net income | C6: 3407 | D6: 2812 | E6: 1842
B7: Adjustments to reconcile net income to net cash from operating activities
B8: Deferred income taxes | C8: -2 | D8: 30 | E8: 20
B9: Depreciation and amortization | C9: 67 | D9: 65 | E9: 58
B10: Amortization of right-of-use assets | C10: 29 | D10: 29 | E10: 26
B11: Employee stock plan compensation | C11: 112 | D11: 100 | E11: 92
B12: Unrealized (gains) losses on other investments, net | C12: -12 | D12: -14 | E12: 8
B13: (Gain) loss on remeasurement of Tax Receivable Agreement liability | C13: 10 | D13: -7 | E13: -6
B14: Bad debt expense | C14: 15 | D14: 7 | E14: 3
B15: Impairment loss | C15: 0 | D15: 0 | E15: 1
B16: Shares distributed to customers under IBKR Promotions | C16: 23 | D16: 12 | E16: 9
B17: Change in operating assets and liabilities
B18: Securities - segregated for regulatory purposes | C18: 7540 | D18: -3605 | E18: -16660
B19: Securities borrowed | C19: 466 | D19: -1086 | E19: -837
B20: Securities purchased under agreements to resell | C20: -1071 | D20: 525 | E20: -1649
B21: Financial instruments owned, at fair value | C21: -434 | D21: -1033 | E21: 189
B22: Receivables from customers | C22: -19975 | D22: -5719 | E22: 16172
B23: Other receivables | C23: -624 | D23: 1792 | E23: 88
B24: Other assets | C24: -203 | D24: -103 | E24: 35
B25: Securities loaned | C25: 4901 | D25: 2407 | E25: -2829
B26: Financial instruments sold, but not yet purchased, at fair value | C26: 100 | D26: 47 | E26: -36
B27: Payable to customers | C27: 14331 | D27: 7817 | E27: 7561
B28: Other payables | C28: 44 | D28: 468 | E28: -119
B29: Net cash provided by operating activities | C29: 8724 | D29: 4544 | E29: 3968
B31: Cash flows from investing activities
B32: Purchases of other investments | C32: -40 | D32: -26 | E32: -5
B33: Distributions received and proceeds from sales of other investments | C33: 45 | D33: 23 | E33: 7
B34: Purchase of property, equipment and intangible assets | C34: -49 | D34: -49 | E34: -69
B35: Net cash used in investing activities | C35: -44 | D35: -52 | E35: -67
B37: Cash flows from financing activities
B38: Short-term borrowings, net | C38: -3 | D38: -1 | E38: -9
B39: Dividends paid to stockholders | C39: -92 | D39: -42 | E39: -40
B40: Distributions to noncontrolling interests | C40: -715 | D40: -556 | E40: -404
B41: Repurchases of common stock for employee tax withholdings | C41: -54 | D41: -34 | E41: -20
B42: Proceeds from the sale of treasury stock | C42: 56 | D42: 34 | E42: 23
B43: Payments made under the Tax Receivable Agreement | C43: -25 | D43: -25 | E43: -20
B44: Net cash used in financing activities | C44: -833 | D44: -624 | E44: -470
...

Sheet Cash Flow - Расчёты
B2: АНАЛИЗ CASH FLOW: КАЧЕСТВО ПРИБЫЛИ И РАСПРЕДЕЛЕНИЕ ДЕНЕЖНОГО ПОТОКА
B4: 1. QUALITY OF EARNINGS: совпадает ли прибыль с реальными деньгами
B5: Показатель | C5: 2024 | D5: 2023 | E5: 2022 | F5: Комментарий
B6: Net income, $ млн | C6: ='Cash Flow - Входные данные'!C6 -> 3407 | D6: ='Cash Flow - Входные данные'!D6 -> 2812 | E6: ='Cash Flow - Входные данные'!E6 -> 1842 | F6: >1.0x — прибыль подтверждена деньгами, не «бумажная»
B7: Net cash from operating activities, $ млн | C7: ='Cash Flow - Входные данные'!C29 -> 8724 | D7: ='Cash Flow - Входные данные'!D29 -> 4544 | E7: ='Cash Flow - Входные данные'!E29 -> 3968
B8: Quality of Earnings ratio (OCF / Net income) | C8: =C7/C6 -> 2.5606105 | D8: =D7/D6 -> 1.6159317 | E8: =E7/E6 -> 2.1541802
B10: 2. FREE CASH FLOW
B11: Показатель | C11: 2024 | D11: 2023 | E11: 2022 | F11: Комментарий
B12: Capex (Purchase of property, equipment and intangible assets), $ млн | C12: ='Cash Flow - Входные данные'!C34 -> -49 | D12: ='Cash Flow - Входные данные'!D34 -> -49 | E12: ='Cash Flow - Входные данные'!E34 -> -69 | F12: У брокера capex минимален — почти весь операционный поток свободен
B13: Free Cash Flow = OCF + Capex (capex уже со знаком минус), $ млн | C13: =C7+C12 -> 8675 | D13: =D7+D12 -> 4495 | E13: =E7+E12 -> 3899
B14: FCF margin (FCF / Net income), % | C14: =C13/C6 -> 2.5462284 | D14: =D13/D6 -> 1.5985064 | E14: =E13/E6 -> 2.116721
B16: 3. РАСПРЕДЕЛЕНИЕ ДЕНЕЖНОГО ПОТОКА: акционеры IBKR vs Holdings (NCI)
B17: Показатель | C17: 2024 | D17: 2023 | E17: 2022 | F17: Комментарий
B18: Dividends paid to stockholders, $ млн | C18: =-'Cash Flow - Входные данные'!C39 -> 92 | D18: =-'Cash Flow - Входные данные'!D39 -> 42 | E18: =-'Cash Flow - Входные данные'!E39 -> 40 | F18: Доля выплат ≈ доле владения (74.2%) — само по себе это пропорционально, не сигнал проблемы
B19: Distributions to noncontrolling interests, $ млн | C19: =-'Cash Flow - Входные данные'!C40 -> 715 | D19: =-'Cash Flow - Входные данные'!D40 -> 556 | E19: =-'Cash Flow - Входные данные'!E40 -> 404
B20: Итого выплат деньгами (dividends + distributions), $ млн | C20: =C18+C19 -> 807 | D20: =D18+D19 -> 598 | E20: =E18+E19 -> 444
B21: Доля акционеров IBKR в выплатах, % | C21: =C18/C20 -> 0.11400248 | D21: =D18/D20 -> 0.070234114 | E21: =E18/E20 -> 0.09009009
B22: Доля Holdings (NCI) в выплатах, % | C22: =C19/C20 -> 0.88599752 | D22: =D19/D20 -> 0.92976589 | E22: =E19/E20 -> 0.90990991
B24: 4. PAYOUT RATIO: какую долю СВОЕЙ прибыли каждая сторона забирает деньгами
B25: Показатель | C25: 2024 | D25: 2023 | E25: 2022 | F25: Комментарий
B26: Net income available for common stockholders, $ млн | C26: 755 | D26: 600 | E26: 380 | F26: Holdings стабильно забирает деньгами на 15-18 п.п. больше своей доли прибыли — точный механизм ниже, см. раздел 5 (TRA)
B27: Net income attributable to NCI, $ млн | C27: 2652 | D27: 2212 | E27: 1462
B28: Payout to common stockholders (Dividends paid / NI available for common), % | C28: =C18/C26 -> 0.1218543 | D28: =D18/D26 -> 0.07 | E28: =E18/E26 -> 0.10526316
B29: Payout to Holdings/NCI (Distributions / NI attributable to NCI), % | C29: =C19/C27 -> 0.26960784 | D29: =D19/D27 -> 0.25135624 | E29: =E19/E27 -> 0.27633379
B30: Разрыв: Payout Holdings минус Payout акционеров, п.п. | C30: =(C29-C28)*100 -> 14.775354 | D30: =(D29-D28)*100 -> 18.135624 | E30: =(E29-E28)*100 -> 17.107063
B32: 5. ПОЧЕМУ HOLDINGS ЗАБИРАЕТ ДЕНЬГАМИ БОЛЬШЕ СВОЕЙ ДОЛИ: TAX RECEIVABLE AGREEMENT
B33: Механизм (документально подтверждён в Note 4 "Equity and Earnings per Share", 10-K FY2024): когда IBG, Inc. выкупает доли у Holdings (через IPO или последующие redemption-сделки), у IBG, Inc. возникает налоговый "step-up" в базе активов — право на дополнительные налоговые вычеты в будущем. По Tax Receivable Agreement IBG, Inc. обязана выплачивать Holdings 85% от реально реализованной налоговой экономии от этого step-up; оставшиеся 15% остаются у IBG, Inc. как permanent increase к Additional paid-in capital.
B34: Платежи по TRA — это ОТДЕЛЬНАЯ статья денежного потока (см. лист 'Cash Flow - Входные данные', строка 'Payments made under the Tax Receivable Agreement': $25M в 2024, $25M в 2023, $20M в 2022), идущая от IBG, Inc. в пользу Holdings ПОВЕРХ обычного пропорционального распределения прибыли. Именно эта дополнительная статья и создаёт payout gap, посчитанный в разделе 4 — это не предположение, а прямое контрактное обязательство, не зависящее от текущей прибыльности бизнеса.
B35: Дополнительный факт (Note 4, 10-K FY2024): средневзвешенная доля IBG, Inc. в ПРИБЫЛИ IBG LLC за 2024 год составила примерно 25.6% (выросла с 25.0% в 2023) — это отдельное число от точечной доли владения КАПИТАЛОМ на конец года (25.8%, см. лист 'NCI и EPS-разрыв'). Разница между этими двумя показателями — техническая (среднегодовая доля в потоке прибыли vs точечная доля на отчётную дату), не отдельный структурный эффект.
B37: ИТОГОВЫЙ ИНСАЙТ: Quality of Earnings ratio в 2024 = 2.56x — операционный денежный поток значительно превышает бухгалтерскую прибыль, то есть прибыль IBKR полностью подтверждена реальными деньгами, а не «застряла» в дебиторке (рост Receivables from customers компенсируется ростом Payable to customers — это нормальная механика брокера, не проблема качества прибыли). Holdings (NCI) забирает деньгами заметно большую долю своей прибыли (~27%), чем акционеры IBKR забирают своей (~12%) — точная, документально подтверждённая причина: контрактные выплаты по Tax Receivable Agreement (85% от налоговой экономии IBG, Inc.) идут в пользу Holdings поверх обычного распределения прибыли, см. раздел 5.

Sheet Данные (плоская таблица)
B2: ТАБЛИЦА ДАННЫХ
B4: Год | C4: Категория | D4: Статья | E4: Значение, $ млн
B5: 2024 | C5: P&L | D5: Commissions | E5: ='Входные данные'!C3 -> 1697
B6: 2023 | C6: P&L | D6: Commissions | E6: ='Входные данные'!D3 -> 1360
B7: 2024 | C7: P&L | D7: Other fees and services | E7: ='Входные данные'!C4 -> 280
B8: 2023 | C8: P&L | D8: Other fees and services | E8: ='Входные данные'!D4 -> 197
B9: 2024 | C9: P&L | D9: Total non-interest income | E9: ='Входные данные'!C6 -> 2037
B10: 2023 | C10: P&L | D10: Total non-interest income | E10: ='Входные данные'!D6 -> 1546
B11: 2024 | C11: P&L | D11: Total net interest income | E11: ='Входные данные'!C9 -> 3148
B12: 2023 | C12: P&L | D12: Total net interest income | E12: ='Входные данные'!D9 -> 2794
B13: 2024 | C13: P&L | D13: Total net revenues | E13: ='Входные данные'!C10 -> 5185
B14: 2023 | C14: P&L | D14: Total net revenues | E14: ='Входные данные'!D10 -> 4340
B15: 2024 | C15: P&L | D15: Total non-interest expenses | E15: ='Входные данные'!C17 -> 1490
B16: 2023 | C16: P&L | D16: Total non-interest expenses | E16: ='Входные данные'!D17 -> 1271
B17: 2024 | C17: P&L | D17: Income before income taxes | E17: ='Входные данные'!C18 -> 3695
B18: 2023 | C18: P&L | D18: Income before income taxes | E18: ='Входные данные'!D18 -> 3069
B19: 2024 | C19: P&L | D19: Net income | E19: ='Входные данные'!C20 -> 3407
B20: 2023 | C20: P&L | D20: Net income | E20: ='Входные данные'!D20 -> 2812
B21: 2024 | C21: P&L | D21: Net income attributable to noncontrolling interests | E21: ='Входные данные'!C21 -> 2652
B22: 2023 | C22: P&L | D22: Net income attributable to noncontrolling interests | E22: ='Входные данные'!D21 -> 2212
B23: 2024 | C23: P&L | D23: Net income available for common stockholders | E23: ='Входные данные'!C22 -> 755
B24: 2023 | C24: P&L | D24: Net income available for common stockholders | E24: ='Входные данные'!D22 -> 600
B25: 2024 | C25: Баланс | D25: Total assets | E25: ='Входные данные'!C29 -> 150518
B26: 2023 | C26: Баланс | D26: Total assets | E26: ='Входные данные'!D29 -> 128423
B27: 2024 | C27: Баланс | D27: Total liabilities | E27: ='Входные данные'!C32 -> 133921
B28: 2023 | C28: Баланс | D28: Total liabilities | E28: ='Входные данные'!D32 -> 114356
B29: 2024 | C29: Баланс | D29: Stockholders' equity (IBG, Inc.) | E29: ='Входные данные'!C33 -> 4280
B30: 2023 | C30: Баланс | D30: Stockholders' equity (IBG, Inc.) | E30: ='Входные данные'!D33 -> 3584
B31: 2024 | C31: Баланс | D31: Noncontrolling interests | E31: ='Входные данные'!C34 -> 12317
B32: 2023 | C32: Баланс | D32: Noncontrolling interests | E32: ='Входные данные'!D34 -> 10483
B33: 2024 | C33: Баланс | D33: Total equity | E33: ='Входные данные'!C35 -> 16597
B34: 2023 | C34: Баланс | D34: Total equity | E34: ='Входные данные'!D35 -> 14067
B35: 2024 | C35: Операционные метрики | D35: Customer accounts, тыс. (на конец года) | E35: ='Входные данные'!C44 -> 3337
B36: 2023 | C36: Операционные метрики | D36: Customer accounts, тыс. (на конец года) | E36: ='Входные данные'!D44 -> 2562
B37: 2024 | C37: Операционные метрики | D37: Customer equity, $ млрд (на конец года) | E37: ='Входные данные'!C45 -> 568.2
B38: 2023 | C38: Операционные метрики | D38: Customer equity, $ млрд (на конец года) | E38: ='Входные данные'!D45 -> 426
B39: 2024 | C39: Операционные метрики | D39: Total customer DARTs, тыс. (среднее в Q4) | E39: ='Входные данные'!C46 -> 3118
B40: 2023 | C40: Операционные метрики | D40: Total customer DARTs, тыс. (среднее в Q4) | E40: ='Входные данные'!D46 -> 1934
B41: 2024 | C41: Операционные метрики | D41: Customer margin loans, $ млрд (на конец года) | E41: ='Входные данные'!C48 -> 64.2
B42: 2023 | C42: Операционные метрики | D42: Customer margin loans, $ млрд (на конец года) | E42: ='Входные данные'!D48 -> 44.3
...

Sheet Свод (интерактивный)
B2: ИНТЕРАКТИВНЫЙ СВОД
B4: Выберите категорию: | C4: P&L
B6: СВОДНАЯ ТАБЛИЦА: Статья × Год (для выбранной категории)
B7: Статья | C7: 2024 | D7: 2023 | E7: 2022 | F7: Δ 2024 vs 2023, %
B8: =IF($C$4="P&L","Commissions",IF($C$4="Баланс","Total assets",IF($C$4="Операционные метрики","Customer accounts, тыс. (на конец года)","Net income"))) -> Commissions | C8: =IF($B8="","",IFERROR(SUMIFS('Данные (плоская таблица)'!$E$5:$E$60,'Данные (плоская таблица)'!$C$5:$C$60,$C$4,'Данные (плоская таблица)'!$D$5:$D$60,$B8,'Данные (плоская таблица)'!$B$5:$B$60,2024),"")) -> 1697 | D8: =IF($B8="","",IFERROR(SUMIFS('Данные (плоская таблица)'!$E$5:$E$60,'Данные (плоская таблица)'!$C$5:$C$60,$C$4,'Данные (плоская таблица)'!$D$5:$D$60,$B8,'Данные (плоская таблица)'!$B$5:$B$60,2023),"")) -> 1360 | E8: =IF($B8="","",IFERROR(SUMIFS('Данные (плоская таблица)'!$E$5:$E$60,'Данные (плоская таблица)'!$C$5:$C$60,$C$4,'Данные (плоская таблица)'!$D$5:$D$60,$B8,'Данные (плоская таблица)'!$B$5:$B$60,2022),"")) -> 0 | F8: =IF($B8="","",IFERROR((C8-D8)/ABS(D8),"")) -> 0.24779412
B9: =IF($C$4="P&L","Other fees and services",IF($C$4="Баланс","Total liabilities",IF($C$4="Операционные метрики","Customer equity, $ млрд (на конец года)","Net cash provided by operating activities"))) -> Other fees and services | C9: =IF($B9="","",IFERROR(SUMIFS('Данные (плоская таблица)'!$E$5:$E$60,'Данные (плоская таблица)'!$C$5:$C$60,$C$4,'Данные (плоская таблица)'!$D$5:$D$60,$B9,'Данные (плоская таблица)'!$B$5:$B$60,2024),"")) -> 280 | D9: =IF($B9="","",IFERROR(SUMIFS('Данные (плоская таблица)'!$E$5:$E$60,'Данные (плоская таблица)'!$C$5:$C$60,$C$4,'Данные (плоская таблица)'!$D$5:$D$60,$B9,'Данные (плоская таблица)'!$B$5:$B$60,2023),"")) -> 197 | E9: =IF($B9="","",IFERROR(SUMIFS('Данные (плоская таблица)'!$E$5:$E$60,'Данные (плоская таблица)'!$C$5:$C$60,$C$4,'Данные (плоская таблица)'!$D$5:$D$60,$B9,'Данные (плоская таблица)'!$B$5:$B$60,2022),"")) -> 0 | F9: =IF($B9="","",IFERROR((C9-D9)/ABS(D9),"")) -> 0.4213198
B10: =IF($C$4="P&L","Total non-interest income",IF($C$4="Баланс","Stockholders' equity (IBG, Inc.)",IF($C$4="Операционные метрики","Total customer DARTs, тыс. (среднее в Q4)","Net cash used in investing activities"))) -> Total non-interest income | C10: =IF($B10="","",IFERROR(SUMIFS('Данные (плоская таблица)'!$E$5:$E$60,'Данные (плоская таблица)'!$C$5:$C$60,$C$4,'Данные (плоская таблица)'!$D$5:$D$60,$B10,'Данные (плоская таблица)'!$B$5:$B$60,2024),"")) -> 2037 | D10: =IF($B10="","",IFERROR(SUMIFS('Данные (плоская таблица)'!$E$5:$E$60,'Данные (плоская таблица)'!$C$5:$C$60,$C$4,'Данные (плоская таблица)'!$D$5:$D$60,$B10,'Данные (плоская таблица)'!$B$5:$B$60,2023),"")) -> 1546 | E10: =IF($B10="","",IFERROR(SUMIFS('Данные (плоская таблица)'!$E$5:$E$60,'Данные (плоская таблица)'!$C$5:$C$60,$C$4,'Данные (плоская таблица)'!$D$5:$D$60,$B10,'Данные (плоская таблица)'!$B$5:$B$60,2022),"")) -> 0 | F10: =IF($B10="","",IFERROR((C10-D10)/ABS(D10),"")) -> 0.31759379
B11: =IF($C$4="P&L","Total net interest income",IF($C$4="Баланс","Noncontrolling interests",IF($C$4="Операционные метрики","Customer margin loans, $ млрд (на конец года)","Net cash used in financing activities"))) -> Total net interest income | C11: =IF($B11="","",IFERROR(SUMIFS('Данные (плоская таблица)'!$E$5:$E$60,'Данные (плоская таблица)'!$C$5:$C$60,$C$4,'Данные (плоская таблица)'!$D$5:$D$60,$B11,'Данные (плоская таблица)'!$B$5:$B$60,2024),"")) -> 3148 | D11: =IF($B11="","",IFERROR(SUMIFS('Данные (плоская таблица)'!$E$5:$E$60,'Данные (плоская таблица)'!$C$5:$C$60,$C$4,'Данные (плоская таблица)'!$D$5:$D$60,$B11,'Данные (плоская таблица)'!$B$5:$B$60,2023),"")) -> 2794 | E11: =IF($B11="","",IFERROR(SUMIFS('Данные (плоская таблица)'!$E$5:$E$60,'Данные (плоская таблица)'!$C$5:$C$60,$C$4,'Данные (плоская таблица)'!$D$5:$D$60,$B11,'Данные (плоская таблица)'!$B$5:$B$60,2022),"")) -> 0 | F11: =IF($B11="","",IFERROR((C11-D11)/ABS(D11),"")) -> 0.12670007
B12: =IF($C$4="P&L","Total net revenues",IF($C$4="Баланс","Total equity",IF($C$4="Операционные метрики","","Dividends paid to stockholders"))) -> Total net revenues | C12: =IF($B12="","",IFERROR(SUMIFS('Данные (плоская таблица)'!$E$5:$E$60,'Данные (плоская таблица)'!$C$5:$C$60,$C$4,'Данные (плоская таблица)'!$D$5:$D$60,$B12,'Данные (плоская таблица)'!$B$5:$B$60,2024),"")) -> 5185 | D12: =IF($B12="","",IFERROR(SUMIFS('Данные (плоская таблица)'!$E$5:$E$60,'Данные (плоская таблица)'!$C$5:$C$60,$C$4,'Данные (плоская таблица)'!$D$5:$D$60,$B12,'Данные (плоская таблица)'!$B$5:$B$60,2023),"")) -> 4340 | E12: =IF($B12="","",IFERROR(SUMIFS('Данные (плоская таблица)'!$E$5:$E$60,'Данные (плоская таблица)'!$C$5:$C$60,$C$4,'Данные (плоская таблица)'!$D$5:$D$60,$B12,'Данные (плоская таблица)'!$B$5:$B$60,2022),"")) -> 0 | F12: =IF($B12="","",IFERROR((C12-D12)/ABS(D12),"")) -> 0.19470046
B13: =IF($C$4="P&L","Total non-interest expenses",IF($C$4="Баланс","",IF($C$4="Операционные метрики","","Distributions to noncontrolling interests"))) -> Total non-interest expenses | C13: =IF($B13="","",IFERROR(SUMIFS('Данные (плоская таблица)'!$E$5:$E$60,'Данные (плоская таблица)'!$C$5:$C$60,$C$4,'Данные (плоская таблица)'!$D$5:$D$60,$B13,'Данные (плоская таблица)'!$B$5:$B$60,2024),"")) -> 1490 | D13: =IF($B13="","",IFERROR(SUMIFS('Данные (плоская таблица)'!$E$5:$E$60,'Данные (плоская таблица)'!$C$5:$C$60,$C$4,'Данные (плоская таблица)'!$D$5:$D$60,$B13,'Данные (плоская таблица)'!$B$5:$B$60,2023),"")) -> 1271 | E13: =IF($B13="","",IFERROR(SUMIFS('Данные (плоская таблица)'!$E$5:$E$60,'Данные (плоская таблица)'!$C$5:$C$60,$C$4,'Данные (плоская таблица)'!$D$5:$D$60,$B13,'Данные (плоская таблица)'!$B$5:$B$60,2022),"")) -> 0 | F13: =IF($B13="","",IFERROR((C13-D13)/ABS(D13),"")) -> 0.17230527
B14: =IF($C$4="P&L","Income before income taxes",IF($C$4="Баланс","",IF($C$4="Операционные метрики","",""))) -> Income before income taxes | C14: =IF($B14="","",IFERROR(SUMIFS('Данные (плоская таблица)'!$E$5:$E$60,'Данные (плоская таблица)'!$C$5:$C$60,$C$4,'Данные (плоская таблица)'!$D$5:$D$60,$B14,'Данные (плоская таблица)'!$B$5:$B$60,2024),"")) -> 3695 | D14: =IF($B14="","",IFERROR(SUMIFS('Данные (плоская таблица)'!$E$5:$E$60,'Данные (плоская таблица)'!$C$5:$C$60,$C$4,'Данные (плоская таблица)'!$D$5:$D$60,$B14,'Данные (плоская таблица)'!$B$5:$B$60,2023),"")) -> 3069 | E14: =IF($B14="","",IFERROR(SUMIFS('Данные (плоская таблица)'!$E$5:$E$60,'Данные (плоская таблица)'!$C$5:$C$60,$C$4,'Данные (плоская таблица)'!$D$5:$D$60,$B14,'Данные (плоская таблица)'!$B$5:$B$60,2022),"")) -> 0 | F14: =IF($B14="","",IFERROR((C14-D14)/ABS(D14),"")) -> 0.20397524
B15: =IF($C$4="P&L","Net income",IF($C$4="Баланс","",IF($C$4="Операционные метрики","",""))) -> Net income | C15: =IF($B15="","",IFERROR(SUMIFS('Данные (плоская таблица)'!$E$5:$E$60,'Данные (плоская таблица)'!$C$5:$C$60,$C$4,'Данные (плоская таблица)'!$D$5:$D$60,$B15,'Данные (плоская таблица)'!$B$5:$B$60,2024),"")) -> 3407 | D15: =IF($B15="","",IFERROR(SUMIFS('Данные (плоская таблица)'!$E$5:$E$60,'Данные (плоская таблица)'!$C$5:$C$60,$C$4,'Данные (плоская таблица)'!$D$5:$D$60,$B15,'Данные (плоская таблица)'!$B$5:$B$60,2023),"")) -> 2812 | E15: =IF($B15="","",IFERROR(SUMIFS('Данные (плоская таблица)'!$E$5:$E$60,'Данные (плоская таблица)'!$C$5:$C$60,$C$4,'Данные (плоская таблица)'!$D$5:$D$60,$B15,'Данные (плоская таблица)'!$B$5:$B$60,2022),"")) -> 0 | F15: =IF($B15="","",IFERROR((C15-D15)/ABS(D15),"")) -> 0.21159317
B16: =IF($C$4="P&L","Net income attributable to noncontrolling interests",IF($C$4="Баланс","",IF($C$4="Операционные метрики","",""))) -> Net income attributable to noncontrolling interests | C16: =IF($B16="","",IFERROR(SUMIFS('Данные (плоская таблица)'!$E$5:$E$60,'Данные (плоская таблица)'!$C$5:$C$60,$C$4,'Данные (плоская таблица)'!$D$5:$D$60,$B16,'Данные (плоская таблица)'!$B$5:$B$60,2024),"")) -> 2652 | D16: =IF($B16="","",IFERROR(SUMIFS('Данные (плоская таблица)'!$E$5:$E$60,'Данные (плоская таблица)'!$C$5:$C$60,$C$4,'Данные (плоская таблица)'!$D$5:$D$60,$B16,'Данные (плоская таблица)'!$B$5:$B$60,2023),"")) -> 2212 | E16: =IF($B16="","",IFERROR(SUMIFS('Данные (плоская таблица)'!$E$5:$E$60,'Данные (плоская таблица)'!$C$5:$C$60,$C$4,'Данные (плоская таблица)'!$D$5:$D$60,$B16,'Данные (плоская таблица)'!$B$5:$B$60,2022),"")) -> 0 | F16: =IF($B16="","",IFERROR((C16-D16)/ABS(D16),"")) -> 0.19891501
B17: =IF($C$4="P&L","Net income available for common stockholders",IF($C$4="Баланс","",IF($C$4="Операционные метрики","",""))) -> Net income available for common stockholders | C17: =IF($B17="","",IFERROR(SUMIFS('Данные (плоская таблица)'!$E$5:$E$60,'Данные (плоская таблица)'!$C$5:$C$60,$C$4,'Данные (плоская таблица)'!$D$5:$D$60,$B17,'Данные (плоская таблица)'!$B$5:$B$60,2024),"")) -> 755 | D17: =IF($B17="","",IFERROR(SUMIFS('Данные (плоская таблица)'!$E$5:$E$60,'Данные (плоская таблица)'!$C$5:$C$60,$C$4,'Данные (плоская таблица)'!$D$5:$D$60,$B17,'Данные (плоская таблица)'!$B$5:$B$60,2023),"")) -> 600 | E17: =IF($B17="","",IFERROR(SUMIFS('Данные (плоская таблица)'!$E$5:$E$60,'Данные (плоская таблица)'!$C$5:$C$60,$C$4,'Данные (плоская таблица)'!$D$5:$D$60,$B17,'Данные (плоская таблица)'!$B$5:$B$60,2022),"")) -> 0 | F17: =IF($B17="","",IFERROR((C17-D17)/ABS(D17),"")) -> 0.25833333

Sheet Графики
B2: Нативные диаграммы
B4: Таблица 1: Net revenues, $ млн (для линейного графика)
B5: Год | C5: Net revenues | D5: Net income
B6: 2023 | C6: ='Входные данные'!D10 -> 4340 | D6: ='Входные данные'!D20 -> 2812
B7: 2024 | C7: ='Входные данные'!C10 -> 5185 | D7: ='Входные данные'!C20 -> 3407
B9: Таблица 2: Структура Net revenues, $ млн
B10: Статья | C10: FY2024 | D10: FY2023
B11: Commissions | C11: ='Входные данные'!C3 -> 1697 | D11: ='Входные данные'!D3 -> 1360
B12: Other fees and services | C12: ='Входные данные'!C4 -> 280 | D12: ='Входные данные'!D4 -> 197
B13: Total net interest income | C13: ='Входные данные'!C9 -> 3148 | D13: ='Входные данные'!D9 -> 2794
B18: Таблица 3: Операционные метрики, индекс FY2023=100
B19: Метрика | C19: FY2023 | D19: FY2024
B20: Accounts | C20: 100 | D20: =100*'Входные данные'!C44/'Входные данные'!D44 -> 130.2498
B21: DARTs | C21: 100 | D21: =100*'Входные данные'!C46/'Входные данные'!D46 -> 161.22027
B22: Margin loans | C22: 100 | D22: =100*'Входные данные'!C48/'Входные данные'!D48 -> 144.92099
B24: Таблица 4: Net income vs Operating Cash Flow, $ млн
B25: Год | C25: Net income | D25: Operating Cash Flow
B26: 2022 | C26: ='Cash Flow - Входные данные'!E6 -> 1842 | D26: ='Cash Flow - Входные данные'!E29 -> 3968
B27: 2023 | C27: ='Cash Flow - Входные данные'!D6 -> 2812 | D27: ='Cash Flow - Входные данные'!D29 -> 4544
B28: 2024 | C28: ='Cash Flow - Входные данные'!C6 -> 3407 | D28: ='Cash Flow - Входные данные'!C29 -> 8724
